<?xml version="1.0" encoding="utf-8"?>
<robot
  name="dofbot">
  <link
    name="base_link">
    <inertial>
      <origin
        xyz="0 0 0"
        rpy="0 0 0" />
      <mass
        value="0.092958" />
      <inertia
        ixx="8.4666E-05"
        ixy="-9.6048E-10"
        ixz="-1.861E-07"
        iyy="0.0003416"
        iyz="-8.8959E-10"
        izz="0.00042523" />
    </inertial>
    <visual>
      <origin
        xyz="0 0 0"
        rpy="0 0 0" />
      <geometry>
        <mesh
          filename="file:///home/robousr/ROS2Dev/robotica_2025_ws/src/dofbot_description/meshes/base_link.STL" />
      </geometry>
      <material
        name="">
        <color
          rgba="0.25098 0.25098 0.25098 1" />
      </material>
    </visual>
    <collision>
      <origin
        xyz="0 0 0"
        rpy="0 0 0" />
      <geometry>
        <mesh
          filename="file:///home/robousr/ROS2Dev/robotica_2025_ws/src/dofbot_description/meshes/base_link.STL" />
      </geometry>
    </collision>
  </link>
  <link
    name="link_1">
    <inertial>
      <origin
        xyz="1.5297E-05 0.00074457 -0.025457"
        rpy="0 0 0" />
      <mass
        value="0.018858" />
      <inertia
        ixx="4.1173E-06"
        ixy="1.8045E-12"
        ixz="-1.0692E-09"
        iyy="3.5744E-06"
        iyz="6.1339E-12"
        izz="6.0516E-06" />
    </inertial>
    <visual>
      <origin
        xyz="0 0 0"
        rpy="0 0 0" />
      <geometry>
        <mesh
          filename="file:///home/robousr/ROS2Dev/robotica_2025_ws/src/dofbot_description/meshes/link_1.STL" />
      </geometry>
      <material
        name="">
        <color
          rgba="0.79216 0.81961 0.93333 1" />
      </material>
    </visual>
    <collision>
      <origin
        xyz="0 0 0"
        rpy="0 0 0" />
      <geometry>
        <mesh
          filename="file:///home/robousr/ROS2Dev/robotica_2025_ws/src/dofbot_description/meshes/link_1.STL" />
      </geometry>
    </collision>
  </link>
  <joint
    name="joint_1"
    type="revolute">
    <origin
      xyz="-8.0366E-05 -0.00065097 0.105"
      rpy="0 0 0" />
    <parent
      link="base_link" />
    <child
      link="link_1" />
    <axis
      xyz="0 0 1" />
    <limit
      lower="-1.5708"
      upper="1.5708"
      effort="30"
      velocity="1" />
  </joint>
  <link
    name="link_2">
    <inertial>
      <origin
        xyz="-0.0036467 0.00025198 0.032368"
        rpy="0 0 0" />
      <mass
        value="0.017459" />
      <inertia
        ixx="6.87E-06"
        ixy="1.101E-09"
        ixz="1.9534E-09"
        iyy="5.644E-06"
        iyz="-2.1596E-09"
        izz="3.0854E-06" />
    </inertial>
    <visual>
      <origin
        xyz="0 0 0"
        rpy="0 0 0" />
      <geometry>
        <mesh
          filename="file:///home/robousr/ROS2Dev/robotica_2025_ws/src/dofbot_description/meshes/link_2.STL" />
      </geometry>
      <material
        name="">
        <color
          rgba="0.79216 0.81961 0.93333 1" />
      </material>
    </visual>
    <collision>
      <origin
        xyz="0 0 0"
        rpy="0 0 0" />
      <geometry>
        <mesh
          filename="file:///home/robousr/ROS2Dev/robotica_2025_ws/src/dofbot_description/meshes/link_2.STL" />
      </geometry>
    </collision>
  </link>
  <joint
    name="joint_2"
    type="revolute">
    <origin
      xyz="0 0 0"
      rpy="0 0 0" />
    <parent
      link="link_1" />
    <child
      link="link_2" />
    <axis
      xyz="0 1 0" />
    <limit
      lower="-1.5708"
      upper="1.5708"
      effort="100"
      velocity="1" />
  </joint>
  <link
    name="link_3">
    <inertial>
      <origin
        xyz="-0.0036611 0.00016719 0.032368"
        rpy="0 0 0" />
      <mass
        value="0.017459" />
      <inertia
        ixx="6.87E-06"
        ixy="1.101E-09"
        ixz="1.9534E-09"
        iyy="5.644E-06"
        iyz="-2.1596E-09"
        izz="3.0854E-06" />
    </inertial>
    <visual>
      <origin
        xyz="0 0 0"
        rpy="0 0 0" />
      <geometry>
        <mesh
          filename="file:///home/robousr/ROS2Dev/robotica_2025_ws/src/dofbot_description/meshes/link_3.STL" />
      </geometry>
      <material
        name="">
        <color
          rgba="0.79216 0.81961 0.93333 1" />
      </material>
    </visual>
    <collision>
      <origin
        xyz="0 0 0"
        rpy="0 0 0" />
      <geometry>
        <mesh
          filename="file:///home/robousr/ROS2Dev/robotica_2025_ws/src/dofbot_description/meshes/link_3.STL" />
      </geometry>
    </collision>
  </link>
  <joint
    name="joint_3"
    type="revolute">
    <origin
      xyz="-4.6503E-05 0.00015021 0.084129"
      rpy="0 0 0" />
    <parent
      link="link_2" />
    <child
      link="link_3" />
    <axis
      xyz="0 1 0" />
    <limit
      lower="-1.5708"
      upper="1.5708"
      effort="100"
      velocity="1" />
  </joint>
  <link
    name="link_4">
    <inertial>
      <origin
        xyz="-0.014537 9.2022E-05 0.041426"
        rpy="0 0 0" />
      <mass
        value="0.033848" />
      <inertia
        ixx="7.6804E-06"
        ixy="9.4895E-10"
        ixz="-8.3101E-07"
        iyy="9.2015E-06"
        iyz="-1.0678E-09"
        izz="6.0262E-06" />
    </inertial>
    <visual>
      <origin
        xyz="0 0 0"
        rpy="0 0 0" />
      <geometry>
        <mesh
          filename="file:///home/robousr/ROS2Dev/robotica_2025_ws/src/dofbot_description/meshes/link_4.STL" />
      </geometry>
      <material
        name="">
        <color
          rgba="0.79216 0.81961 0.93333 1" />
      </material>
    </visual>
    <collision>
      <origin
        xyz="0 0 0"
        rpy="0 0 0" />
      <geometry>
        <mesh
          filename="file:///home/robousr/ROS2Dev/robotica_2025_ws/src/dofbot_description/meshes/link_4.STL" />
      </geometry>
    </collision>
  </link>
  <joint
    name="joint_4"
    type="revolute">
    <origin
      xyz="-6.6502E-05 -0.00014979 0.084129"
      rpy="0 0 0" />
    <parent
      link="link_3" />
    <child
      link="link_4" />
    <axis
      xyz="0 1 0" />
    <limit
      lower="-1.5708"
      upper="1.5708"
      effort="100"
      velocity="1" />
  </joint>
  <link
    name="link_5">
    <inertial>
      <origin
        xyz="0.014695 -0.0025424 0.032914"
        rpy="0 0 0" />
      <mass
        value="0.048874" />
      <inertia
        ixx="8.7445E-06"
        ixy="-2.6708E-08"
        ixz="-2.2767E-08"
        iyy="4.4467E-06"
        iyz="9.8128E-09"
        izz="7.4631E-06" />
    </inertial>
    <visual>
      <origin
        xyz="0 0 0"
        rpy="0 0 0" />
      <geometry>
        <mesh
          filename="file:///home/robousr/ROS2Dev/robotica_2025_ws/src/dofbot_description/meshes/link_5.STL" />
      </geometry>
      <material
        name="">
        <color
          rgba="0.79216 0.81961 0.93333 1" />
      </material>
    </visual>
    <collision>
      <origin
        xyz="0 0 0"
        rpy="0 0 0" />
      <geometry>
        <mesh
          filename="file:///home/robousr/ROS2Dev/robotica_2025_ws/src/dofbot_description/meshes/link_5.STL" />
      </geometry>
    </collision>
  </link>
  <joint
    name="joint_5"
    type="revolute">
    <origin
      xyz="-5.9765E-05 0 0.075245"
      rpy="0 0 0" />
    <parent
      link="link_4" />
    <child
      link="link_5" />
    <axis
      xyz="0 0 1" />
    <limit
      lower="-1.5708"
      upper="1.5708"
      effort="100"
      velocity="1" />
  </joint>
</robot>